Workbook

Sheet Calendrier
A1: Date d'envoi | B1: Jour | C1: Mois | D1: Newsletter | E1: Cible | F1: Langues | G1: Sujet principal | H1: Objet de l'e-mail | I1: Statut | J1: Responsable | K1: Texte FR validé | L1: Traductions prêtes | M1: Programmé dans Brevo | N1: Note
A2: 46310 | B2: =CHOOSE(WEEKDAY(A2,2),"lundi","mardi","mercredi","jeudi","vendredi","samedi","dimanche") -> jeudi | C2: Octobre 2026 | D2: B2B | E2: Partenaires et clients pros | F2: FR, EN, IT, ES, DE, NL, PL | G2: À définir | I2: À rédiger | K2: =WORKDAY(A2,-5,Règles!$A$13:$A$34) -> 46303 | L2: =IF(F2="FR","—",WORKDAY(A2,-3,Règles!$A$13:$A$34)) -> 46307 | M2: =WORKDAY(A2,-1,Règles!$A$13:$A$34) -> 46309
A3: 46325 | B3: =CHOOSE(WEEKDAY(A3,2),"lundi","mardi","mercredi","jeudi","vendredi","samedi","dimanche") -> vendredi | C3: Octobre 2026 | D3: Trucker | E3: Conducteurs (app) | F3: FR, IT | G3: Heure d'hiver : trouver sa place avant la nuit. En bref : Profil Trucker, amis et recommandations, Loi Montagne / obbligo invernale. | H3: Depuis dimanche, la nuit te rattrape | I3: Rédigé | K3: =WORKDAY(A3,-5,Règles!$A$13:$A$34) -> 46318 | L3: =IF(F3="FR","—",WORKDAY(A3,-3,Règles!$A$13:$A$34)) -> 46322 | M3: =WORKDAY(A3,-1,Règles!$A$13:$A$34) -> 46324
A4: 46325 | B4: =CHOOSE(WEEKDAY(A4,2),"lundi","mardi","mercredi","jeudi","vendredi","samedi","dimanche") -> vendredi | C4: Octobre 2026 | D4: Owner | E4: Établissements sur Truckfly | F4: FR | G4: À définir | I4: À rédiger | K4: =WORKDAY(A4,-5,Règles!$A$13:$A$34) -> 46318 | L4: =IF(F4="FR","—",WORKDAY(A4,-3,Règles!$A$13:$A$34)) -> — | M4: =WORKDAY(A4,-1,Règles!$A$13:$A$34) -> 46324
A5: 46328 | B5: =CHOOSE(WEEKDAY(A5,2),"lundi","mardi","mercredi","jeudi","vendredi","samedi","dimanche") -> lundi | C5: Octobre 2026 | D5: Nouveautés Trucker | E5: Conducteurs (app) | F5: FR, IT | G5: À définir | I5: Si nouveauté | K5: =WORKDAY(A5,-5,Règles!$A$13:$A$34) -> 46321 | L5: =IF(F5="FR","—",WORKDAY(A5,-3,Règles!$A$13:$A$34)) -> 46323 | M5: =WORKDAY(A5,-1,Règles!$A$13:$A$34) -> 46325
A6: 46342 | B6: =CHOOSE(WEEKDAY(A6,2),"lundi","mardi","mercredi","jeudi","vendredi","samedi","dimanche") -> lundi | C6: Novembre 2026 | D6: B2B | E6: Partenaires et clients pros | F6: FR, EN, IT, ES, DE, NL, PL | G6: À définir | I6: À rédiger | K6: =WORKDAY(A6,-5,Règles!$A$13:$A$34) -> 46332 | L6: =IF(F6="FR","—",WORKDAY(A6,-3,Règles!$A$13:$A$34)) -> 46336 | M6: =WORKDAY(A6,-1,Règles!$A$13:$A$34) -> 46339 | N6: Le 15 tombe un dimanche : décalé au lundi.
A7: 46353 | B7: =CHOOSE(WEEKDAY(A7,2),"lundi","mardi","mercredi","jeudi","vendredi","samedi","dimanche") -> vendredi | C7: Novembre 2026 | D7: Trucker | E7: Conducteurs (app) | F7: FR, IT | G7: À définir | I7: À rédiger | K7: =WORKDAY(A7,-5,Règles!$A$13:$A$34) -> 46346 | L7: =IF(F7="FR","—",WORKDAY(A7,-3,Règles!$A$13:$A$34)) -> 46350 | M7: =WORKDAY(A7,-1,Règles!$A$13:$A$34) -> 46352
A8: 46353 | B8: =CHOOSE(WEEKDAY(A8,2),"lundi","mardi","mercredi","jeudi","vendredi","samedi","dimanche") -> vendredi | C8: Novembre 2026 | D8: Owner | E8: Établissements sur Truckfly | F8: FR | G8: À définir | I8: À rédiger | K8: =WORKDAY(A8,-5,Règles!$A$13:$A$34) -> 46346 | L8: =IF(F8="FR","—",WORKDAY(A8,-3,Règles!$A$13:$A$34)) -> — | M8: =WORKDAY(A8,-1,Règles!$A$13:$A$34) -> 46352
A9: 46356 | B9: =CHOOSE(WEEKDAY(A9,2),"lundi","mardi","mercredi","jeudi","vendredi","samedi","dimanche") -> lundi | C9: Novembre 2026 | D9: Nouveautés Trucker | E9: Conducteurs (app) | F9: FR, IT | G9: À définir | I9: Si nouveauté | K9: =WORKDAY(A9,-5,Règles!$A$13:$A$34) -> 46349 | L9: =IF(F9="FR","—",WORKDAY(A9,-3,Règles!$A$13:$A$34)) -> 46351 | M9: =WORKDAY(A9,-1,Règles!$A$13:$A$34) -> 46353
A10: 46371 | B10: =CHOOSE(WEEKDAY(A10,2),"lundi","mardi","mercredi","jeudi","vendredi","samedi","dimanche") -> mardi | C10: Décembre 2026 | D10: B2B | E10: Partenaires et clients pros | F10: FR, EN, IT, ES, DE, NL, PL | G10: À définir | I10: À rédiger | K10: =WORKDAY(A10,-5,Règles!$A$13:$A$34) -> 46363 | L10: =IF(F10="FR","—",WORKDAY(A10,-3,Règles!$A$13:$A$34)) -> 46366 | M10: =WORKDAY(A10,-1,Règles!$A$13:$A$34) -> 46370
A11: 46374 | B11: =CHOOSE(WEEKDAY(A11,2),"lundi","mardi","mercredi","jeudi","vendredi","samedi","dimanche") -> vendredi | C11: Décembre 2026 | D11: Trucker | E11: Conducteurs (app) | F11: FR, IT | G11: À définir | I11: À rédiger | K11: =WORKDAY(A11,-5,Règles!$A$13:$A$34) -> 46367 | L11: =IF(F11="FR","—",WORKDAY(A11,-3,Règles!$A$13:$A$34)) -> 46371 | M11: =WORKDAY(A11,-1,Règles!$A$13:$A$34) -> 46373 | N11: Vendredi 25 décembre 2026 : Noël, avancé au vendredi précédent.
A12: 46374 | B12: =CHOOSE(WEEKDAY(A12,2),"lundi","mardi","mercredi","jeudi","vendredi","samedi","dimanche") -> vendredi | C12: Décembre 2026 | D12: Owner | E12: Établissements sur Truckfly | F12: FR | G12: À définir | I12: À rédiger | K12: =WORKDAY(A12,-5,Règles!$A$13:$A$34) -> 46367 | L12: =IF(F12="FR","—",WORKDAY(A12,-3,Règles!$A$13:$A$34)) -> — | M12: =WORKDAY(A12,-1,Règles!$A$13:$A$34) -> 46373 | N12: Vendredi 25 décembre 2026 : Noël, avancé au vendredi précédent.
A13: 46377 | B13: =CHOOSE(WEEKDAY(A13,2),"lundi","mardi","mercredi","jeudi","vendredi","samedi","dimanche") -> lundi | C13: Décembre 2026 | D13: Nouveautés Trucker | E13: Conducteurs (app) | F13: FR, IT | G13: À définir | I13: Si nouveauté | K13: =WORKDAY(A13,-5,Règles!$A$13:$A$34) -> 46370 | L13: =IF(F13="FR","—",WORKDAY(A13,-3,Règles!$A$13:$A$34)) -> 46372 | M13: =WORKDAY(A13,-1,Règles!$A$13:$A$34) -> 46374
A14: 46402 | B14: =CHOOSE(WEEKDAY(A14,2),"lundi","mardi","mercredi","jeudi","vendredi","samedi","dimanche") -> vendredi | C14: Janvier 2027 | D14: B2B | E14: Partenaires et clients pros | F14: FR, EN, IT, ES, DE, NL, PL | G14: À définir | I14: À rédiger | K14: =WORKDAY(A14,-5,Règles!$A$13:$A$34) -> 46395 | L14: =IF(F14="FR","—",WORKDAY(A14,-3,Règles!$A$13:$A$34)) -> 46399 | M14: =WORKDAY(A14,-1,Règles!$A$13:$A$34) -> 46401
A15: 46416 | B15: =CHOOSE(WEEKDAY(A15,2),"lundi","mardi","mercredi","jeudi","vendredi","samedi","dimanche") -> vendredi | C15: Janvier 2027 | D15: Trucker | E15: Conducteurs (app) | F15: FR, IT | G15: À définir | I15: À rédiger | K15: =WORKDAY(A15,-5,Règles!$A$13:$A$34) -> 46409 | L15: =IF(F15="FR","—",WORKDAY(A15,-3,Règles!$A$13:$A$34)) -> 46413 | M15: =WORKDAY(A15,-1,Règles!$A$13:$A$34) -> 46415
A16: 46416 | B16: =CHOOSE(WEEKDAY(A16,2),"lundi","mardi","mercredi","jeudi","vendredi","samedi","dimanche") -> vendredi | C16: Janvier 2027 | D16: Owner | E16: Établissements sur Truckfly | F16: FR | G16: À définir | I16: À rédiger | K16: =WORKDAY(A16,-5,Règles!$A$13:$A$34) -> 46409 | L16: =IF(F16="FR","—",WORKDAY(A16,-3,Règles!$A$13:$A$34)) -> — | M16: =WORKDAY(A16,-1,Règles!$A$13:$A$34) -> 46415
A17: 46419 | B17: =CHOOSE(WEEKDAY(A17,2),"lundi","mardi","mercredi","jeudi","vendredi","samedi","dimanche") -> lundi | C17: Janvier 2027 | D17: Nouveautés Trucker | E17: Conducteurs (app) | F17: FR, IT | G17: À définir | I17: Si nouveauté | K17: =WORKDAY(A17,-5,Règles!$A$13:$A$34) -> 46412 | L17: =IF(F17="FR","—",WORKDAY(A17,-3,Règles!$A$13:$A$34)) -> 46414 | M17: =WORKDAY(A17,-1,Règles!$A$13:$A$34) -> 46416
A18: 46433 | B18: =CHOOSE(WEEKDAY(A18,2),"lundi","mardi","mercredi","jeudi","vendredi","samedi","dimanche") -> lundi | C18: Février 2027 | D18: B2B | E18: Partenaires et clients pros | F18: FR, EN, IT, ES, DE, NL, PL | G18: À définir | I18: À rédiger | K18: =WORKDAY(A18,-5,Règles!$A$13:$A$34) -> 46426 | L18: =IF(F18="FR","—",WORKDAY(A18,-3,Règles!$A$13:$A$34)) -> 46428 | M18: =WORKDAY(A18,-1,Règles!$A$13:$A$34) -> 46430
A19: 46444 | B19: =CHOOSE(WEEKDAY(A19,2),"lundi","mardi","mercredi","jeudi","vendredi","samedi","dimanche") -> vendredi | C19: Février 2027 | D19: Trucker | E19: Conducteurs (app) | F19: FR, IT | G19: À définir | I19: À rédiger | K19: =WORKDAY(A19,-5,Règles!$A$13:$A$34) -> 46437 | L19: =IF(F19="FR","—",WORKDAY(A19,-3,Règles!$A$13:$A$34)) -> 46441 | M19: =WORKDAY(A19,-1,Règles!$A$13:$A$34) -> 46443
A20: 46444 | B20: =CHOOSE(WEEKDAY(A20,2),"lundi","mardi","mercredi","jeudi","vendredi","samedi","dimanche") -> vendredi | C20: Février 2027 | D20: Owner | E20: Établissements sur Truckfly | F20: FR | G20: À définir | I20: À rédiger | K20: =WORKDAY(A20,-5,Règles!$A$13:$A$34) -> 46437 | L20: =IF(F20="FR","—",WORKDAY(A20,-3,Règles!$A$13:$A$34)) -> — | M20: =WORKDAY(A20,-1,Règles!$A$13:$A$34) -> 46443
A21: 46447 | B21: =CHOOSE(WEEKDAY(A21,2),"lundi","mardi","mercredi","jeudi","vendredi","samedi","dimanche") -> lundi | C21: Février 2027 | D21: Nouveautés Trucker | E21: Conducteurs (app) | F21: FR, IT | G21: À définir | I21: Si nouveauté | K21: =WORKDAY(A21,-5,Règles!$A$13:$A$34) -> 46440 | L21: =IF(F21="FR","—",WORKDAY(A21,-3,Règles!$A$13:$A$34)) -> 46442 | M21: =WORKDAY(A21,-1,Règles!$A$13:$A$34) -> 46444
A22: 46461 | B22: =CHOOSE(WEEKDAY(A22,2),"lundi","mardi","mercredi","jeudi","vendredi","samedi","dimanche") -> lundi | C22: Mars 2027 | D22: B2B | E22: Partenaires et clients pros | F22: FR, EN, IT, ES, DE, NL, PL | G22: À définir | I22: À rédiger | K22: =WORKDAY(A22,-5,Règles!$A$13:$A$34) -> 46454 | L22: =IF(F22="FR","—",WORKDAY(A22,-3,Règles!$A$13:$A$34)) -> 46456 | M22: =WORKDAY(A22,-1,Règles!$A$13:$A$34) -> 46458
A23: 46472 | B23: =CHOOSE(WEEKDAY(A23,2),"lundi","mardi","mercredi","jeudi","vendredi","samedi","dimanche") -> vendredi | C23: Mars 2027 | D23: Trucker | E23: Conducteurs (app) | F23: FR, IT | G23: À définir | I23: À rédiger | K23: =WORKDAY(A23,-5,Règles!$A$13:$A$34) -> 46465 | L23: =IF(F23="FR","—",WORKDAY(A23,-3,Règles!$A$13:$A$34)) -> 46469 | M23: =WORKDAY(A23,-1,Règles!$A$13:$A$34) -> 46471 | N23: Vendredi saint (férié en Allemagne et en Espagne, pas en France ni en Italie).
A24: 46472 | B24: =CHOOSE(WEEKDAY(A24,2),"lundi","mardi","mercredi","jeudi","vendredi","samedi","dimanche") -> vendredi | C24: Mars 2027 | D24: Owner | E24: Établissements sur Truckfly | F24: FR | G24: À définir | I24: À rédiger | K24: =WORKDAY(A24,-5,Règles!$A$13:$A$34) -> 46465 | L24: =IF(F24="FR","—",WORKDAY(A24,-3,Règles!$A$13:$A$34)) -> — | M24: =WORKDAY(A24,-1,Règles!$A$13:$A$34) -> 46471 | N24: Vendredi saint (férié en Allemagne et en Espagne, pas en France ni en Italie).
A25: 46476 | B25: =CHOOSE(WEEKDAY(A25,2),"lundi","mardi","mercredi","jeudi","vendredi","samedi","dimanche") -> mardi | C25: Mars 2027 | D25: Nouveautés Trucker | E25: Conducteurs (app) | F25: FR, IT | G25: À définir | I25: Si nouveauté | K25: =WORKDAY(A25,-5,Règles!$A$13:$A$34) -> 46468 | L25: =IF(F25="FR","—",WORKDAY(A25,-3,Règles!$A$13:$A$34)) -> 46470 | M25: =WORKDAY(A25,-1,Règles!$A$13:$A$34) -> 46472 | N25: Lundi de Pâques : décalé au mardi.
A26: 46492 | B26: =CHOOSE(WEEKDAY(A26,2),"lundi","mardi","mercredi","jeudi","vendredi","samedi","dimanche") -> jeudi | C26: Avril 2027 | D26: B2B | E26: Partenaires et clients pros | F26: FR, EN, IT, ES, DE, NL, PL | G26: À définir | I26: À rédiger | K26: =WORKDAY(A26,-5,Règles!$A$13:$A$34) -> 46485 | L26: =IF(F26="FR","—",WORKDAY(A26,-3,Règles!$A$13:$A$34)) -> 46489 | M26: =WORKDAY(A26,-1,Règles!$A$13:$A$34) -> 46491
A27: 46507 | B27: =CHOOSE(WEEKDAY(A27,2),"lundi","mardi","mercredi","jeudi","vendredi","samedi","dimanche") -> vendredi | C27: Avril 2027 | D27: Trucker | E27: Conducteurs (app) | F27: FR, IT | G27: À définir | I27: À rédiger | K27: =WORKDAY(A27,-5,Règles!$A$13:$A$34) -> 46500 | L27: =IF(F27="FR","—",WORKDAY(A27,-3,Règles!$A$13:$A$34)) -> 46504 | M27: =WORKDAY(A27,-1,Règles!$A$13:$A$34) -> 46506
A28: 46507 | B28: =CHOOSE(WEEKDAY(A28,2),"lundi","mardi","mercredi","jeudi","vendredi","samedi","dimanche") -> vendredi | C28: Avril 2027 | D28: Owner | E28: Établissements sur Truckfly | F28: FR | G28: À définir | I28: À rédiger | K28: =WORKDAY(A28,-5,Règles!$A$13:$A$34) -> 46500 | L28: =IF(F28="FR","—",WORKDAY(A28,-3,Règles!$A$13:$A$34)) -> — | M28: =WORKDAY(A28,-1,Règles!$A$13:$A$34) -> 46506
A29: 46510 | B29: =CHOOSE(WEEKDAY(A29,2),"lundi","mardi","mercredi","jeudi","vendredi","samedi","dimanche") -> lundi | C29: Avril 2027 | D29: Nouveautés Trucker | E29: Conducteurs (app) | F29: FR, IT | G29: À définir | I29: Si nouveauté | K29: =WORKDAY(A29,-5,Règles!$A$13:$A$34) -> 46503 | L29: =IF(F29="FR","—",WORKDAY(A29,-3,Règles!$A$13:$A$34)) -> 46505 | M29: =WORKDAY(A29,-1,Règles!$A$13:$A$34) -> 46507
A30: 46521 | B30: =CHOOSE(WEEKDAY(A30,2),"lundi","mardi","mercredi","jeudi","vendredi","samedi","dimanche") -> vendredi | C30: Mai 2027 | D30: B2B | E30: Partenaires et clients pros | F30: FR, EN, IT, ES, DE, NL, PL | G30: À définir | I30: À rédiger | K30: =WORKDAY(A30,-5,Règles!$A$13:$A$34) -> 46514 | L30: =IF(F30="FR","—",WORKDAY(A30,-3,Règles!$A$13:$A$34)) -> 46518 | M30: =WORKDAY(A30,-1,Règles!$A$13:$A$34) -> 46520 | N30: Le 15 tombe un samedi : avancé au vendredi.
A31: 46535 | B31: =CHOOSE(WEEKDAY(A31,2),"lundi","mardi","mercredi","jeudi","vendredi","samedi","dimanche") -> vendredi | C31: Mai 2027 | D31: Trucker | E31: Conducteurs (app) | F31: FR, IT | G31: À définir | I31: À rédiger | K31: =WORKDAY(A31,-5,Règles!$A$13:$A$34) -> 46528 | L31: =IF(F31="FR","—",WORKDAY(A31,-3,Règles!$A$13:$A$34)) -> 46532 | M31: =WORKDAY(A31,-1,Règles!$A$13:$A$34) -> 46534
A32: 46535 | B32: =CHOOSE(WEEKDAY(A32,2),"lundi","mardi","mercredi","jeudi","vendredi","samedi","dimanche") -> vendredi | C32: Mai 2027 | D32: Owner | E32: Établissements sur Truckfly | F32: FR | G32: À définir | I32: À rédiger | K32: =WORKDAY(A32,-5,Règles!$A$13:$A$34) -> 46528 | L32: =IF(F32="FR","—",WORKDAY(A32,-3,Règles!$A$13:$A$34)) -> — | M32: =WORKDAY(A32,-1,Règles!$A$13:$A$34) -> 46534
A33: 46538 | B33: =CHOOSE(WEEKDAY(A33,2),"lundi","mardi","mercredi","jeudi","vendredi","samedi","dimanche") -> lundi | C33: Mai 2027 | D33: Nouveautés Trucker | E33: Conducteurs (app) | F33: FR, IT | G33: À définir | I33: Si nouveauté | K33: =WORKDAY(A33,-5,Règles!$A$13:$A$34) -> 46531 | L33: =IF(F33="FR","—",WORKDAY(A33,-3,Règles!$A$13:$A$34)) -> 46533 | M33: =WORKDAY(A33,-1,Règles!$A$13:$A$34) -> 46535
A34: 46553 | B34: =CHOOSE(WEEKDAY(A34,2),"lundi","mardi","mercredi","jeudi","vendredi","samedi","dimanche") -> mardi | C34: Juin 2027 | D34: B2B | E34: Partenaires et clients pros | F34: FR, EN, IT, ES, DE, NL, PL | G34: À définir | I34: À rédiger | K34: =WORKDAY(A34,-5,Règles!$A$13:$A$34) -> 46546 | L34: =IF(F34="FR","—",WORKDAY(A34,-3,Règles!$A$13:$A$34)) -> 46548 | M34: =WORKDAY(A34,-1,Règles!$A$13:$A$34) -> 46552
A35: 46563 | B35: =CHOOSE(WEEKDAY(A35,2),"lundi","mardi","mercredi","jeudi","vendredi","samedi","dimanche") -> vendredi | C35: Juin 2027 | D35: Trucker | E35: Conducteurs (app) | F35: FR, IT | G35: À définir | I35: À rédiger | K35: =WORKDAY(A35,-5,Règles!$A$13:$A$34) -> 46556 | L35: =IF(F35="FR","—",WORKDAY(A35,-3,Règles!$A$13:$A$34)) -> 46560 | M35: =WORKDAY(A35,-1,Règles!$A$13:$A$34) -> 46562
A36: 46563 | B36: =CHOOSE(WEEKDAY(A36,2),"lundi","mardi","mercredi","jeudi","vendredi","samedi","dimanche") -> vendredi | C36: Juin 2027 | D36: Owner | E36: Établissements sur Truckfly | F36: FR | G36: À définir | I36: À rédiger | K36: =WORKDAY(A36,-5,Règles!$A$13:$A$34) -> 46556 | L36: =IF(F36="FR","—",WORKDAY(A36,-3,Règles!$A$13:$A$34)) -> — | M36: =WORKDAY(A36,-1,Règles!$A$13:$A$34) -> 46562
A37: 46566 | B37: =CHOOSE(WEEKDAY(A37,2),"lundi","mardi","mercredi","jeudi","vendredi","samedi","dimanche") -> lundi | C37: Juin 2027 | D37: Nouveautés Trucker | E37: Conducteurs (app) | F37: FR, IT | G37: À définir | I37: Si nouveauté | K37: =WORKDAY(A37,-5,Règles!$A$13:$A$34) -> 46559 | L37: =IF(F37="FR","—",WORKDAY(A37,-3,Règles!$A$13:$A$34)) -> 46561 | M37: =WORKDAY(A37,-1,Règles!$A$13:$A$34) -> 46563
A38: 46583 | B38: =CHOOSE(WEEKDAY(A38,2),"lundi","mardi","mercredi","jeudi","vendredi","samedi","dimanche") -> jeudi | C38: Juillet 2027 | D38: B2B | E38: Partenaires et clients pros | F38: FR, EN, IT, ES, DE, NL, PL | G38: À définir | I38: À rédiger | K38: =WORKDAY(A38,-5,Règles!$A$13:$A$34) -> 46575 | L38: =IF(F38="FR","—",WORKDAY(A38,-3,Règles!$A$13:$A$34)) -> 46577 | M38: =WORKDAY(A38,-1,Règles!$A$13:$A$34) -> 46581
A39: 46598 | B39: =CHOOSE(WEEKDAY(A39,2),"lundi","mardi","mercredi","jeudi","vendredi","samedi","dimanche") -> vendredi | C39: Juillet 2027 | D39: Trucker | E39: Conducteurs (app) | F39: FR, IT | G39: À définir | I39: À rédiger | K39: =WORKDAY(A39,-5,Règles!$A$13:$A$34) -> 46591 | L39: =IF(F39="FR","—",WORKDAY(A39,-3,Règles!$A$13:$A$34)) -> 46595 | M39: =WORKDAY(A39,-1,Règles!$A$13:$A$34) -> 46597
A40: 46598 | B40: =CHOOSE(WEEKDAY(A40,2),"lundi","mardi","mercredi","jeudi","vendredi","samedi","dimanche") -> vendredi | C40: Juillet 2027 | D40: Owner | E40: Établissements sur Truckfly | F40: FR | G40: À définir | I40: À rédiger | K40: =WORKDAY(A40,-5,Règles!$A$13:$A$34) -> 46591 | L40: =IF(F40="FR","—",WORKDAY(A40,-3,Règles!$A$13:$A$34)) -> — | M40: =WORKDAY(A40,-1,Règles!$A$13:$A$34) -> 46597
...

Sheet Règles
A1: Mode d'emploi
A3: Cases à remplir | B3: Fond jaune clair dans Calendrier : Sujet principal, Objet, Statut, Responsable.
A4: Exemple | B4: La ligne Trucker du 30 octobre 2026 est remplie.
A5: B2B | B5: Le 15 du mois. Samedi : vendredi 14. Dimanche : lundi 16. Jour férié : jour ouvré suivant.
A6: Trucker et Owner | B6: Le dernier vendredi du mois. Jour férié, 24 ou 31 décembre : vendredi précédent.
A7: Nouveautés Trucker | B7: Le lundi qui suit l'envoi Trucker, seulement s'il y a une nouveauté. Jour férié : mardi.
A8: Échéances (proposition) | B8: Texte FR validé : 5 jours ouvrés avant l'envoi. Traductions prêtes : 3 jours ouvrés avant. Programmé dans Brevo : 1 jour ouvré avant. Calculées à partir de la date d'envoi et des jours fériés ci-dessous.
A9: Changer une date | B9: Modifier la date d'envoi dans Calendrier : jour, échéances et Vue par mois se mettent à jour.
A11: Jours fériés pris en compte (France et Italie)
A12: Date | B12: Jour | C12: Férié
A13: 46327 | B13: dimanche 1 novembre 2026 | C13: Toussaint
A14: 46337 | B14: mercredi 11 novembre 2026 | C14: Armistice (FR)
A15: 46364 | B15: mardi 8 décembre 2026 | C15: Immacolata (IT)
A16: 46381 | B16: vendredi 25 décembre 2026 | C16: Noël
A17: 46382 | B17: samedi 26 décembre 2026 | C17: Santo Stefano (IT)
A18: 46388 | B18: vendredi 1 janvier 2027 | C18: Jour de l'an
A19: 46393 | B19: mercredi 6 janvier 2027 | C19: Epifania (IT)
A20: 46474 | B20: dimanche 28 mars 2027 | C20: Pâques
A21: 46475 | B21: lundi 29 mars 2027 | C21: Lundi de Pâques
A22: 46502 | B22: dimanche 25 avril 2027 | C22: Liberazione (IT)
A23: 46508 | B23: samedi 1 mai 2027 | C23: Fête du travail
A24: 46513 | B24: jeudi 6 mai 2027 | C24: Ascension (FR)
... A34: 46747 | B34: dimanche 26 décembre 2027 | C34: Santo Stefano (IT)

Sheet Vue par mois
A1: Mois | B1: B2B | C1: Trucker | D1: Owner | E1: Nouveautés Trucker
A2: Octobre 2026 | B2: =_xlfn.MINIFS(Calendrier!$A$2:$A$61,Calendrier!$C$2:$C$61,$A2,Calendrier!$D$2:$D$61,"B2B") -> 46310 | C2: =_xlfn.MINIFS(Calendrier!$A$2:$A$61,Calendrier!$C$2:$C$61,$A2,Calendrier!$D$2:$D$61,"Trucker") -> 46325 | D2: =_xlfn.MINIFS(Calendrier!$A$2:$A$61,Calendrier!$C$2:$C$61,$A2,Calendrier!$D$2:$D$61,"Owner") -> 46325 | E2: =_xlfn.MINIFS(Calendrier!$A$2:$A$61,Calendrier!$C$2:$C$61,$A2,Calendrier!$D$2:$D$61,"Nouveautés Trucker") -> 46328
A3: Novembre 2026 | B3: =_xlfn.MINIFS(Calendrier!$A$2:$A$61,Calendrier!$C$2:$C$61,$A3,Calendrier!$D$2:$D$61,"B2B") -> 46342 | C3: =_xlfn.MINIFS(Calendrier!$A$2:$A$61,Calendrier!$C$2:$C$61,$A3,Calendrier!$D$2:$D$61,"Trucker") -> 46353 | D3: =_xlfn.MINIFS(Calendrier!$A$2:$A$61,Calendrier!$C$2:$C$61,$A3,Calendrier!$D$2:$D$61,"Owner") -> 46353 | E3: =_xlfn.MINIFS(Calendrier!$A$2:$A$61,Calendrier!$C$2:$C$61,$A3,Calendrier!$D$2:$D$61,"Nouveautés Trucker") -> 46356
A4: Décembre 2026 | B4: =_xlfn.MINIFS(Calendrier!$A$2:$A$61,Calendrier!$C$2:$C$61,$A4,Calendrier!$D$2:$D$61,"B2B") -> 46371 | C4: =_xlfn.MINIFS(Calendrier!$A$2:$A$61,Calendrier!$C$2:$C$61,$A4,Calendrier!$D$2:$D$61,"Trucker") -> 46374 | D4: =_xlfn.MINIFS(Calendrier!$A$2:$A$61,Calendrier!$C$2:$C$61,$A4,Calendrier!$D$2:$D$61,"Owner") -> 46374 | E4: =_xlfn.MINIFS(Calendrier!$A$2:$A$61,Calendrier!$C$2:$C$61,$A4,Calendrier!$D$2:$D$61,"Nouveautés Trucker") -> 46377
A5: Janvier 2027 | B5: =_xlfn.MINIFS(Calendrier!$A$2:$A$61,Calendrier!$C$2:$C$61,$A5,Calendrier!$D$2:$D$61,"B2B") -> 46402 | C5: =_xlfn.MINIFS(Calendrier!$A$2:$A$61,Calendrier!$C$2:$C$61,$A5,Calendrier!$D$2:$D$61,"Trucker") -> 46416 | D5: =_xlfn.MINIFS(Calendrier!$A$2:$A$61,Calendrier!$C$2:$C$61,$A5,Calendrier!$D$2:$D$61,"Owner") -> 46416 | E5: =_xlfn.MINIFS(Calendrier!$A$2:$A$61,Calendrier!$C$2:$C$61,$A5,Calendrier!$D$2:$D$61,"Nouveautés Trucker") -> 46419
A6: Février 2027 | B6: =_xlfn.MINIFS(Calendrier!$A$2:$A$61,Calendrier!$C$2:$C$61,$A6,Calendrier!$D$2:$D$61,"B2B") -> 46433 | C6: =_xlfn.MINIFS(Calendrier!$A$2:$A$61,Calendrier!$C$2:$C$61,$A6,Calendrier!$D$2:$D$61,"Trucker") -> 46444 | D6: =_xlfn.MINIFS(Calendrier!$A$2:$A$61,Calendrier!$C$2:$C$61,$A6,Calendrier!$D$2:$D$61,"Owner") -> 46444 | E6: =_xlfn.MINIFS(Calendrier!$A$2:$A$61,Calendrier!$C$2:$C$61,$A6,Calendrier!$D$2:$D$61,"Nouveautés Trucker") -> 46447
A7: Mars 2027 | B7: =_xlfn.MINIFS(Calendrier!$A$2:$A$61,Calendrier!$C$2:$C$61,$A7,Calendrier!$D$2:$D$61,"B2B") -> 46461 | C7: =_xlfn.MINIFS(Calendrier!$A$2:$A$61,Calendrier!$C$2:$C$61,$A7,Calendrier!$D$2:$D$61,"Trucker") -> 46472 | D7: =_xlfn.MINIFS(Calendrier!$A$2:$A$61,Calendrier!$C$2:$C$61,$A7,Calendrier!$D$2:$D$61,"Owner") -> 46472 | E7: =_xlfn.MINIFS(Calendrier!$A$2:$A$61,Calendrier!$C$2:$C$61,$A7,Calendrier!$D$2:$D$61,"Nouveautés Trucker") -> 46476
A8: Avril 2027 | B8: =_xlfn.MINIFS(Calendrier!$A$2:$A$61,Calendrier!$C$2:$C$61,$A8,Calendrier!$D$2:$D$61,"B2B") -> 46492 | C8: =_xlfn.MINIFS(Calendrier!$A$2:$A$61,Calendrier!$C$2:$C$61,$A8,Calendrier!$D$2:$D$61,"Trucker") -> 46507 | D8: =_xlfn.MINIFS(Calendrier!$A$2:$A$61,Calendrier!$C$2:$C$61,$A8,Calendrier!$D$2:$D$61,"Owner") -> 46507 | E8: =_xlfn.MINIFS(Calendrier!$A$2:$A$61,Calendrier!$C$2:$C$61,$A8,Calendrier!$D$2:$D$61,"Nouveautés Trucker") -> 46510
A9: Mai 2027 | B9: =_xlfn.MINIFS(Calendrier!$A$2:$A$61,Calendrier!$C$2:$C$61,$A9,Calendrier!$D$2:$D$61,"B2B") -> 46521 | C9: =_xlfn.MINIFS(Calendrier!$A$2:$A$61,Calendrier!$C$2:$C$61,$A9,Calendrier!$D$2:$D$61,"Trucker") -> 46535 | D9: =_xlfn.MINIFS(Calendrier!$A$2:$A$61,Calendrier!$C$2:$C$61,$A9,Calendrier!$D$2:$D$61,"Owner") -> 46535 | E9: =_xlfn.MINIFS(Calendrier!$A$2:$A$61,Calendrier!$C$2:$C$61,$A9,Calendrier!$D$2:$D$61,"Nouveautés Trucker") -> 46538
A10: Juin 2027 | B10: =_xlfn.MINIFS(Calendrier!$A$2:$A$61,Calendrier!$C$2:$C$61,$A10,Calendrier!$D$2:$D$61,"B2B") -> 46553 | C10: =_xlfn.MINIFS(Calendrier!$A$2:$A$61,Calendrier!$C$2:$C$61,$A10,Calendrier!$D$2:$D$61,"Trucker") -> 46563 | D10: =_xlfn.MINIFS(Calendrier!$A$2:$A$61,Calendrier!$C$2:$C$61,$A10,Calendrier!$D$2:$D$61,"Owner") -> 46563 | E10: =_xlfn.MINIFS(Calendrier!$A$2:$A$61,Calendrier!$C$2:$C$61,$A10,Calendrier!$D$2:$D$61,"Nouveautés Trucker") -> 46566
A11: Juillet 2027 | B11: =_xlfn.MINIFS(Calendrier!$A$2:$A$61,Calendrier!$C$2:$C$61,$A11,Calendrier!$D$2:$D$61,"B2B") -> 46583 | C11: =_xlfn.MINIFS(Calendrier!$A$2:$A$61,Calendrier!$C$2:$C$61,$A11,Calendrier!$D$2:$D$61,"Trucker") -> 46598 | D11: =_xlfn.MINIFS(Calendrier!$A$2:$A$61,Calendrier!$C$2:$C$61,$A11,Calendrier!$D$2:$D$61,"Owner") -> 46598 | E11: =_xlfn.MINIFS(Calendrier!$A$2:$A$61,Calendrier!$C$2:$C$61,$A11,Calendrier!$D$2:$D$61,"Nouveautés Trucker") -> 46601
A12: Août 2027 | B12: =_xlfn.MINIFS(Calendrier!$A$2:$A$61,Calendrier!$C$2:$C$61,$A12,Calendrier!$D$2:$D$61,"B2B") -> 46615 | C12: =_xlfn.MINIFS(Calendrier!$A$2:$A$61,Calendrier!$C$2:$C$61,$A12,Calendrier!$D$2:$D$61,"Trucker") -> 46626 | D12: =_xlfn.MINIFS(Calendrier!$A$2:$A$61,Calendrier!$C$2:$C$61,$A12,Calendrier!$D$2:$D$61,"Owner") -> 46626 | E12: =_xlfn.MINIFS(Calendrier!$A$2:$A$61,Calendrier!$C$2:$C$61,$A12,Calendrier!$D$2:$D$61,"Nouveautés Trucker") -> 46629
A13: Septembre 2027 | B13: =_xlfn.MINIFS(Calendrier!$A$2:$A$61,Calendrier!$C$2:$C$61,$A13,Calendrier!$D$2:$D$61,"B2B") -> 46645 | C13: =_xlfn.MINIFS(Calendrier!$A$2:$A$61,Calendrier!$C$2:$C$61,$A13,Calendrier!$D$2:$D$61,"Trucker") -> 46654 | D13: =_xlfn.MINIFS(Calendrier!$A$2:$A$61,Calendrier!$C$2:$C$61,$A13,Calendrier!$D$2:$D$61,"Owner") -> 46654 | E13: =_xlfn.MINIFS(Calendrier!$A$2:$A$61,Calendrier!$C$2:$C$61,$A13,Calendrier!$D$2:$D$61,"Nouveautés Trucker") -> 46657
... A16: Décembre 2027 | B16: =_xlfn.MINIFS(Calendrier!$A$2:$A$61,Calendrier!$C$2:$C$61,$A16,Calendrier!$D$2:$D$61,"B2B") -> 46736 | C16: =_xlfn.MINIFS(Calendrier!$A$2:$A$61,Calendrier!$C$2:$C$61,$A16,Calendrier!$D$2:$D$61,"Trucker") -> 46738 | D16: =_xlfn.MINIFS(Calendrier!$A$2:$A$61,Calendrier!$C$2:$C$61,$A16,Calendrier!$D$2:$D$61,"Owner") -> 46738 | E16: =_xlfn.MINIFS(Calendrier!$A$2:$A$61,Calendrier!$C$2:$C$61,$A16,Calendrier!$D$2:$D$61,"Nouveautés Trucker") -> 46741
